Workbook

Sheet Sheet1
A1: TITLE | B1: MAGNITUDE | C1: DATE_TIME | D1: CDI | E1: MMI | F1: ALERT | G1: TSUNAMI | H1: SIG | I1: NET | J1: NST | K1: DMIN | L1: GAP | M1: MAGTYPE | N1: DEPTH | O1: LATITUDE | P1: LONGITUDE | Q1: LOCATION | R1: CONTINENT | S1: COUNTRY

Sheet Exploration
A1: Task 1 - Excel-Based Exploration
A3: Metric | B3: Value | G3: Magnitude Band | H3: Count | J3: Title Pattern | K3: Count
A4: Number of records | B4: =COUNTA(Raw_Data!A2:A1001) -> 1000 | G4: 6.5-<7.0 | H4: =COUNTIFS(Raw_Data!B2:B1001,">=6.5",Raw_Data!B2:B1001,"<7") -> 627 | J4: Distance/location | K4: =COUNTIF(Raw_Data!W2:W1001,J4) -> 849
A5: Number of columns | B5: =COUNTA(Raw_Data!B1:S1) -> 18 | G5: 7.0-<7.5 | H5: =COUNTIFS(Raw_Data!B2:B1001,">=7",Raw_Data!B2:B1001,"<7.5") -> 229 | J5: Named-region | K5: =COUNTIF(Raw_Data!W2:W1001,J5) -> 0
A6: Minimum magnitude | B6: =MIN(Raw_Data!B2:B1001) -> 6.5 | G6: 7.5-<8.0 | H6: =COUNTIFS(Raw_Data!B2:B1001,">=7.5",Raw_Data!B2:B1001,"<8") -> 112
A7: Maximum magnitude | B7: =MAX(Raw_Data!B2:B1001) -> 9.1 | G7: 8.0-<8.5 | H7: =COUNTIFS(Raw_Data!B2:B1001,">=8",Raw_Data!B2:B1001,"<8.5") -> 27
A8: Average magnitude | B8: =AVERAGE(Raw_Data!B2:B1001) -> 6.94015 | G8: 8.5-<9.0 | H8: =COUNTIFS(Raw_Data!B2:B1001,">=8.5",Raw_Data!B2:B1001,"<9") -> 3
A9: Minimum depth | B9: =MIN(Raw_Data!N2:N1001) -> 2.7 | G9: 9.0+ | H9: =COUNTIF(Raw_Data!B2:B1001,">=9") -> 2
A10: Maximum depth | B10: =MAX(Raw_Data!N2:N1001) -> 670.81
A11: Average depth | B11: =AVERAGE(Raw_Data!N2:N1001) -> 74.612541

Sheet Data_Type_Audit
A1: Task 2 - Data Type and Quality Audit
A3: Column | B3: Data Type | C3: Reason
A4: Title | B4: Text | C4: Descriptive earthquake title
A5: Magnitude | B5: Numeric | C5: Numerical earthquake magnitude
A6: Date_Time | B6: Text | C6: Stored as text in raw dataset
A7: CDI | B7: Numeric | C7: Numerical intensity value
A8: MMI | B8: Numeric | C8: Numerical intensity value
A9: Alert | B9: Categorial | C9: Hazard-level categories
A10: Tsunami | B10: Categorial | C10: Binary/category indicator
A11: SIG | B11: Numeric | C11: Numerical significance score
A12: NET | B12: Categorial | C12: Network/source code
A13: NST | B13: Numeric | C13: Numerical station count
A14: DMIN | B14: Numeric | C14: Numerical minimum distance
... A22: Country | B22: Categorial | C22: Geographic category

Sheet Missing_Audit
A1: Missing Value Audit
A3: Field | B3: Blank Count | C3: Blank Percentage
A4: alert | B4: =COUNTBLANK(Raw_Data!F2:F1001) -> 551 | C4: =B4/1000 -> 0.551
A5: continent | B5: =COUNTBLANK(Raw_Data!R2:R1001) -> 716 | C5: =B5/1000 -> 0.716
A6: country | B6: =COUNTBLANK(Raw_Data!S2:S1001) -> 349 | C6: =B6/1000 -> 0.349
A7: location | B7: =COUNTBLANK(Raw_Data!Q2:Q1001) -> 6 | C7: =B7/1000 -> 0.006

Sheet Raw_Data
A1: title | B1: magnitude | C1: date_time | D1: cdi | E1: mmi | F1: alert | G1: tsunami | H1: sig | I1: net | J1: nst | K1: dmin | L1: gap | M1: magType | N1: depth | O1: latitude | P1: longitude | Q1: location | R1: continent | S1: country | T1: date_time_converted | U1: converted_is_number | V1: raw_date_is_number | W1: title_pattern | X1: magType_normalized | Y1: duplicate_count | Z1: duplicate_flag | AA1: date_status
A2: M 6.5 - 42 km W of Sola, Vanuatu | B2: 6.5 | C2: 16/08/2023 12:47 | D2: 7 | E2: 4 | F2: green | G2: 0 | H2: 657 | I2: us | J2: 114 | K2: 7.177 | L2: 25 | M2: mww | N2: 192.955 | O2: -13.8814 | P2: 167.158 | Q2: Sola, Vanuatu | S2: Vanuatu | T2: =IF(C2="","",IF(ISNUMBER(C2),DATE(YEAR(C2),DAY(C2),MONTH(C2))+TIME(HOUR(C2),MINUTE(C2),SECOND(C2)),DATE(VALUE(MID(C2,7,4)),VALUE(MID(C2,4,2)),VALUE(MID(C2,1,2)))+TIME(VALUE(MID(C2,12,2)),VALUE(MID(C2,15,2)),0))) -> 45154.533 | U2: =ISNUMBER(T2) -> TRUE | V2: =ISNUMBER(C2) -> FALSE | W2: =IFERROR(__xludf.DUMMYFUNCTION("IF(REGEXMATCH(A2,""[0-9]+(\.[0-9]+)?\s*km""),""Distance/Location"",""Named Region"")"),"Distance/Location") -> Distance/Location | X2: =LOWER(M2) -> mww | Y2: =COUNTIFS($A$2:$A$1001,A2,$C$2:$C$1001,C2) -> 1 | Z2: =IF(Y2>1,"Duplicate","Unique") -> Unique | AA2: =IF(U2=TRUE,"Valid","Invalid") -> Valid
A3: M 6.5 - 43 km S of Intipucá, El Salvador | B3: 6.5 | C3: 19/07/2023 00:22 | D3: 8 | E3: 6 | F3: yellow | G3: 0 | H3: 775 | I3: us | J3: 92 | K3: 0.679 | L3: 40 | M3: mww | N3: 69.727 | O3: 12.814 | P3: -88.1265 | Q3: Intipucá, El Salvador | T3: =IF(C3="","",IF(ISNUMBER(C3),DATE(YEAR(C3),DAY(C3),MONTH(C3))+TIME(HOUR(C3),MINUTE(C3),SECOND(C3)),DATE(VALUE(MID(C3,7,4)),VALUE(MID(C3,4,2)),VALUE(MID(C3,1,2)))+TIME(VALUE(MID(C3,12,2)),VALUE(MID(C3,15,2)),0))) -> 45126.015 | U3: =ISNUMBER(T3) -> TRUE | V3: =ISNUMBER(C3) -> FALSE | W3: =IFERROR(__xludf.DUMMYFUNCTION("IF(REGEXMATCH(A3,""[0-9]+(\.[0-9]+)?\s*km""),""Distance/Location"",""Named Region"")"),"Distance/Location") -> Distance/Location | X3: =LOWER(M3) -> mww | Y3: =COUNTIFS($A$2:$A$1001,A3,$C$2:$C$1001,C3) -> 1 | Z3: =IF(Y3>1,"Duplicate","Unique") -> Unique | AA3: =IF(U3=TRUE,"Valid","Invalid") -> Valid
A4: M 6.6 - 25 km ESE of Loncopué, Argentina | B4: 6.6 | C4: 17/07/2023 03:05 | D4: 7 | E4: 5 | F4: green | G4: 0 | H4: 899 | I4: us | J4: 70 | K4: 1.634 | L4: 28 | M4: mww | N4: 171.371 | O4: -38.1911 | P4: -70.3731 | Q4: Loncopué, Argentina | R4: South America | S4: Argentina | T4: =IF(C4="","",IF(ISNUMBER(C4),DATE(YEAR(C4),DAY(C4),MONTH(C4))+TIME(HOUR(C4),MINUTE(C4),SECOND(C4)),DATE(VALUE(MID(C4,7,4)),VALUE(MID(C4,4,2)),VALUE(MID(C4,1,2)))+TIME(VALUE(MID(C4,12,2)),VALUE(MID(C4,15,2)),0))) -> 45124.128 | U4: =ISNUMBER(T4) -> TRUE | V4: =ISNUMBER(C4) -> FALSE | W4: =IFERROR(__xludf.DUMMYFUNCTION("IF(REGEXMATCH(A4,""[0-9]+(\.[0-9]+)?\s*km""),""Distance/Location"",""Named Region"")"),"Distance/Location") -> Distance/Location | X4: =LOWER(M4) -> mww | Y4: =COUNTIFS($A$2:$A$1001,A4,$C$2:$C$1001,C4) -> 1 | Z4: =IF(Y4>1,"Duplicate","Unique") -> Unique | AA4: =IF(U4=TRUE,"Valid","Invalid") -> Valid
A5: M 7.2 - 98 km S of Sand Point, Alaska | B5: 7.2 | C5: 16/07/2023 06:48 | D5: 6 | E5: 6 | F5: green | G5: 1 | H5: 860 | I5: us | J5: 173 | K5: 0.907 | L5: 36 | M5: mww | N5: 32.571 | O5: 54.3844 | P5: -160.699 | Q5: Sand Point, Alaska | T5: =IF(C5="","",IF(ISNUMBER(C5),DATE(YEAR(C5),DAY(C5),MONTH(C5))+TIME(HOUR(C5),MINUTE(C5),SECOND(C5)),DATE(VALUE(MID(C5,7,4)),VALUE(MID(C5,4,2)),VALUE(MID(C5,1,2)))+TIME(VALUE(MID(C5,12,2)),VALUE(MID(C5,15,2)),0))) -> 45123.283 | U5: =ISNUMBER(T5) -> TRUE | V5: =ISNUMBER(C5) -> FALSE | W5: =IFERROR(__xludf.DUMMYFUNCTION("IF(REGEXMATCH(A5,""[0-9]+(\.[0-9]+)?\s*km""),""Distance/Location"",""Named Region"")"),"Distance/Location") -> Distance/Location | X5: =LOWER(M5) -> mww | Y5: =COUNTIFS($A$2:$A$1001,A5,$C$2:$C$1001,C5) -> 1 | Z5: =IF(Y5>1,"Duplicate","Unique") -> Unique | AA5: =IF(U5=TRUE,"Valid","Invalid") -> Valid
A6: M 7.3 - Alaska Peninsula | B6: 7.3 | C6: 16/07/2023 06:48 | D6: 0 | E6: 5 | G6: 1 | H6: 820 | I6: at | J6: 79 | K6: 0.879451 | L6: 172.8 | M6: Mi | N6: 21 | O6: 54.49 | P6: -160.796 | Q6: Alaska Peninsula | T6: =IF(C6="","",IF(ISNUMBER(C6),DATE(YEAR(C6),DAY(C6),MONTH(C6))+TIME(HOUR(C6),MINUTE(C6),SECOND(C6)),DATE(VALUE(MID(C6,7,4)),VALUE(MID(C6,4,2)),VALUE(MID(C6,1,2)))+TIME(VALUE(MID(C6,12,2)),VALUE(MID(C6,15,2)),0))) -> 45123.283 | U6: =ISNUMBER(T6) -> TRUE | V6: =ISNUMBER(C6) -> FALSE | W6: =IFERROR(__xludf.DUMMYFUNCTION("IF(REGEXMATCH(A6,""[0-9]+(\.[0-9]+)?\s*km""),""Distance/Location"",""Named Region"")"),"Named Region") -> Named Region | X6: =LOWER(M6) -> mi | Y6: =COUNTIFS($A$2:$A$1001,A6,$C$2:$C$1001,C6) -> 1 | Z6: =IF(Y6>1,"Duplicate","Unique") -> Unique | AA6: =IF(U6=TRUE,"Valid","Invalid") -> Valid
A7: M 6.6 - 277 km NNE of Codrington, Antigua and Barbuda | B7: 6.6 | C7: 45206.853 | D7: 5 | E7: 4 | F7: green | G7: 1 | H7: 802 | I7: us | J7: 95 | K7: 2.454 | L7: 37 | M7: mww | N7: 10 | O7: 20.0196 | P7: -61.0955 | Q7: Codrington, Antigua and Barbuda | T7: =IF(C7="","",IF(ISNUMBER(C7),DATE(YEAR(C7),DAY(C7),MONTH(C7))+TIME(HOUR(C7),MINUTE(C7),SECOND(C7)),DATE(VALUE(MID(C7,7,4)),VALUE(MID(C7,4,2)),VALUE(MID(C7,1,2)))+TIME(VALUE(MID(C7,12,2)),VALUE(MID(C7,15,2)),0))) -> 45117.853 | U7: =ISNUMBER(T7) -> TRUE | V7: =ISNUMBER(C7) -> TRUE | W7: =IFERROR(__xludf.DUMMYFUNCTION("IF(REGEXMATCH(A7,""[0-9]+(\.[0-9]+)?\s*km""),""Distance/Location"",""Named Region"")"),"Distance/Location") -> Distance/Location | X7: =LOWER(M7) -> mww | Y7: =COUNTIFS($A$2:$A$1001,A7,$C$2:$C$1001,C7) -> 1 | Z7: =IF(Y7>1,"Duplicate","Unique") -> Unique | AA7: =IF(U7=TRUE,"Valid","Invalid") -> Valid
A8: M 6.9 - Tonga | B8: 6.9 | C8: 44964.435 | D8: 4 | E8: 4 | F8: green | G8: 1 | H8: 741 | I8: us | J8: 136 | K8: 1.179 | L8: 23 | M8: mww | N8: 229 | O8: -17.853 | P8: -174.937 | Q8: Tonga | T8: =IF(C8="","",IF(ISNUMBER(C8),DATE(YEAR(C8),DAY(C8),MONTH(C8))+TIME(HOUR(C8),MINUTE(C8),SECOND(C8)),DATE(VALUE(MID(C8,7,4)),VALUE(MID(C8,4,2)),VALUE(MID(C8,1,2)))+TIME(VALUE(MID(C8,12,2)),VALUE(MID(C8,15,2)),0))) -> 45109.435 | U8: =ISNUMBER(T8) -> TRUE | V8: =ISNUMBER(C8) -> TRUE | W8: =IF(ISNUMBER(SEARCH(" km ",A8)),"Distance/Location","Named Region") -> Named Region | X8: =LOWER(M8) -> mww | Y8: =COUNTIFS($A$2:$A$1001,A8,$C$2:$C$1001,C8) -> 1 | Z8: =IF(Y8>1,"Duplicate","Unique") -> Unique | AA8: =IF(U8=TRUE,"Valid","Invalid") -> Valid
A9: M 7.2 - south of the Fiji Islands | B9: 7.2 | C9: 15/06/2023 18:06 | D9: 8 | E9: 6 | F9: green | G9: 1 | H9: 804 | I9: us | J9: 85 | K9: 2.59 | L9: 24 | M9: mww | N9: 167.404 | O9: -22.9824 | P9: -177.208 | Q9: the Fiji Islands | T9: =IF(C9="","",IF(ISNUMBER(C9),DATE(YEAR(C9),DAY(C9),MONTH(C9))+TIME(HOUR(C9),MINUTE(C9),SECOND(C9)),DATE(VALUE(MID(C9,7,4)),VALUE(MID(C9,4,2)),VALUE(MID(C9,1,2)))+TIME(VALUE(MID(C9,12,2)),VALUE(MID(C9,15,2)),0))) -> 45092.754 | U9: =ISNUMBER(T9) -> TRUE | V9: =ISNUMBER(C9) -> FALSE | W9: =IF(ISNUMBER(SEARCH(" km ",A9)),"Distance/Location","Named Region") -> Named Region | X9: =LOWER(M9) -> mww | Y9: =COUNTIFS($A$2:$A$1001,A9,$C$2:$C$1001,C9) -> 1 | Z9: =IF(Y9>1,"Duplicate","Unique") -> Unique | AA9: =IF(U9=TRUE,"Valid","Invalid") -> Valid
A10: M 6.6 - Panama-Colombia border region | B10: 6.6 | C10: 25/05/2023 03:05 | D10: 6 | E10: 6 | F10: green | G10: 1 | H10: 733 | I10: us | J10: 50 | K10: 2.163 | L10: 129 | M10: mww | N10: 10 | O10: 8.8894 | P10: -77.1231 | Q10: Panama-Colombia border region | S10: Colombia | T10: =IF(C10="","",IF(ISNUMBER(C10),DATE(YEAR(C10),DAY(C10),MONTH(C10))+TIME(HOUR(C10),MINUTE(C10),SECOND(C10)),DATE(VALUE(MID(C10,7,4)),VALUE(MID(C10,4,2)),VALUE(MID(C10,1,2)))+TIME(VALUE(MID(C10,12,2)),VALUE(MID(C10,15,2)),0))) -> 45071.128 | U10: =ISNUMBER(T10) -> TRUE | V10: =ISNUMBER(C10) -> FALSE | W10: =IF(ISNUMBER(SEARCH(" km ",A10)),"Distance/Location","Named Region") -> Named Region | X10: =LOWER(M10) -> mww | Y10: =COUNTIFS($A$2:$A$1001,A10,$C$2:$C$1001,C10) -> 1 | Z10: =IF(Y10>1,"Duplicate","Unique") -> Unique | AA10: =IF(U10=TRUE,"Valid","Invalid") -> Valid
A11: M 7.1 - southeast of the Loyalty Islands | B11: 7.1 | C11: 20/05/2023 01:51 | D11: 3 | E11: 4 | F11: green | G11: 1 | H11: 777 | I11: us | J11: 98 | K11: 2.812 | L11: 56 | M11: mww | N11: 35.981 | O11: -23.0622 | P11: 170.456 | Q11: the Loyalty Islands | T11: =IF(C11="","",IF(ISNUMBER(C11),DATE(YEAR(C11),DAY(C11),MONTH(C11))+TIME(HOUR(C11),MINUTE(C11),SECOND(C11)),DATE(VALUE(MID(C11,7,4)),VALUE(MID(C11,4,2)),VALUE(MID(C11,1,2)))+TIME(VALUE(MID(C11,12,2)),VALUE(MID(C11,15,2)),0))) -> 45066.077 | U11: =ISNUMBER(T11) -> TRUE | V11: =ISNUMBER(C11) -> FALSE | W11: =IF(ISNUMBER(SEARCH(" km ",A11)),"Distance/Location","Named Region") -> Named Region | X11: =LOWER(M11) -> mww | Y11: =COUNTIFS($A$2:$A$1001,A11,$C$2:$C$1001,C11) -> 1 | Z11: =IF(Y11>1,"Duplicate","Unique") -> Unique | AA11: =IF(U11=TRUE,"Valid","Invalid") -> Valid
A12: M 7.7 - southeast of the Loyalty Islands | B12: 7.7 | C12: 19/05/2023 02:57 | D12: 5 | E12: 4 | F12: green | G12: 1 | H12: 927 | I12: us | J12: 277 | K12: 3.111 | L12: 15 | M12: mww | N12: 18.027 | O12: -23.2286 | P12: 170.694 | Q12: the Loyalty Islands | T12: =IF(C12="","",IF(ISNUMBER(C12),DATE(YEAR(C12),DAY(C12),MONTH(C12))+TIME(HOUR(C12),MINUTE(C12),SECOND(C12)),DATE(VALUE(MID(C12,7,4)),VALUE(MID(C12,4,2)),VALUE(MID(C12,1,2)))+TIME(VALUE(MID(C12,12,2)),VALUE(MID(C12,15,2)),0))) -> 45065.123 | U12: =ISNUMBER(T12) -> TRUE | V12: =ISNUMBER(C12) -> FALSE | W12: =IF(ISNUMBER(SEARCH(" km ",A12)),"Distance/Location","Named Region") -> Named Region | X12: =LOWER(M12) -> mww | Y12: =COUNTIFS($A$2:$A$1001,A12,$C$2:$C$1001,C12) -> 1 | Z12: =IF(Y12>1,"Duplicate","Unique") -> Unique | AA12: =IF(U12=TRUE,"Valid","Invalid") -> Valid
A13: M 7.6 - 95 km WNW of Hihifo, Tonga | B13: 7.6 | C13: 45204.668 | D13: 8 | E13: 6 | F13: green | G13: 1 | H13: 907 | I13: us | J13: 111 | K13: 3.631 | L13: 17 | M13: mww | N13: 210.097 | O13: -15.6002 | P13: -174.608 | Q13: Hihifo, Tonga | T13: =IF(C13="","",IF(ISNUMBER(C13),DATE(YEAR(C13),DAY(C13),MONTH(C13))+TIME(HOUR(C13),MINUTE(C13),SECOND(C13)),DATE(VALUE(MID(C13,7,4)),VALUE(MID(C13,4,2)),VALUE(MID(C13,1,2)))+TIME(VALUE(MID(C13,12,2)),VALUE(MID(C13,15,2)),0))) -> 45056.668 | U13: =ISNUMBER(T13) -> TRUE | V13: =ISNUMBER(C13) -> TRUE | W13: =IF(ISNUMBER(SEARCH(" km ",A13)),"Distance/Location","Named Region") -> Distance/Location | X13: =LOWER(M13) -> mww | Y13: =COUNTIFS($A$2:$A$1001,A13,$C$2:$C$1001,C13) -> 1 | Z13: =IF(Y13>1,"Duplicate","Unique") -> Unique | AA13: =IF(U13=TRUE,"Valid","Invalid") -> Valid
A14: M 6.6 - south of the Fiji Islands | B14: 6.6 | C14: 28/04/2023 03:13 | D14: 0 | E14: 2 | F14: green | G14: 0 | H14: 670 | I14: us | J14: 52 | K14: 5.123 | L14: 50 | M14: mww | N14: 598.467 | O14: -25.2657 | P14: 178.424 | Q14: the Fiji Islands | T14: =IF(C14="","",IF(ISNUMBER(C14),DATE(YEAR(C14),DAY(C14),MONTH(C14))+TIME(HOUR(C14),MINUTE(C14),SECOND(C14)),DATE(VALUE(MID(C14,7,4)),VALUE(MID(C14,4,2)),VALUE(MID(C14,1,2)))+TIME(VALUE(MID(C14,12,2)),VALUE(MID(C14,15,2)),0))) -> 45044.134 | U14: =ISNUMBER(T14) -> TRUE | V14: =ISNUMBER(C14) -> FALSE | W14: =IF(ISNUMBER(SEARCH(" km ",A14)),"Distance/Location","Named Region") -> Named Region | X14: =LOWER(M14) -> mww | Y14: =COUNTIFS($A$2:$A$1001,A14,$C$2:$C$1001,C14) -> 1 | Z14: =IF(Y14>1,"Duplicate","Unique") -> Unique | AA14: =IF(U14=TRUE,"Valid","Invalid") -> Valid
A15: M 7.1 - 170 km SSE of Teluk Dalam, Indonesia | B15: 7.1 | C15: 24/04/2023 20:00 | D15: 9 | E15: 7 | F15: green | G15: 0 | H15: 838 | I15: us | J15: 70 | K15: 2.282 | L15: 58 | M15: mww | N15: 15.462 | O15: -0.781 | P15: 98.5339 | Q15: Teluk Dalam, Indonesia | S15: Indonesia | T15: =IF(C15="","",IF(ISNUMBER(C15),DATE(YEAR(C15),DAY(C15),MONTH(C15))+TIME(HOUR(C15),MINUTE(C15),SECOND(C15)),DATE(VALUE(MID(C15,7,4)),VALUE(MID(C15,4,2)),VALUE(MID(C15,1,2)))+TIME(VALUE(MID(C15,12,2)),VALUE(MID(C15,15,2)),0))) -> 45040.833 | U15: =ISNUMBER(T15) -> TRUE | V15: =ISNUMBER(C15) -> FALSE | W15: =IF(ISNUMBER(SEARCH(" km ",A15)),"Distance/Location","Named Region") -> Distance/Location | X15: =LOWER(M15) -> mww | Y15: =COUNTIFS($A$2:$A$1001,A15,$C$2:$C$1001,C15) -> 1 | Z15: =IF(Y15>1,"Duplicate","Unique") -> Unique | AA15: =IF(U15=TRUE,"Valid","Invalid") -> Valid
A16: M 7.1 - Kermadec Islands, New Zealand | B16: 7.1 | C16: 24/04/2023 00:41 | D16: 8 | E16: 7 | F16: green | G16: 1 | H16: 777 | I16: us | J16: 126 | K16: 0.708 | L16: 23 | M16: mww | N16: 43.063 | O16: -30.0249 | P16: -177.897 | Q16: Kermadec Islands, New Zealand | T16: =IF(C16="","",IF(ISNUMBER(C16),DATE(YEAR(C16),DAY(C16),MONTH(C16))+TIME(HOUR(C16),MINUTE(C16),SECOND(C16)),DATE(VALUE(MID(C16,7,4)),VALUE(MID(C16,4,2)),VALUE(MID(C16,1,2)))+TIME(VALUE(MID(C16,12,2)),VALUE(MID(C16,15,2)),0))) -> 45040.028 | U16: =ISNUMBER(T16) -> TRUE | V16: =ISNUMBER(C16) -> FALSE | W16: =IF(ISNUMBER(SEARCH(" km ",A16)),"Distance/Location","Named Region") -> Named Region | X16: =LOWER(M16) -> mww | Y16: =COUNTIFS($A$2:$A$1001,A16,$C$2:$C$1001,C16) -> 1 | Z16: =IF(Y16>1,"Duplicate","Unique") -> Unique | AA16: =IF(U16=TRUE,"Valid","Invalid") -> Valid
A17: M 6.7 - south of the Fiji Islands | B17: 6.7 | C17: 18/04/2023 04:31 | D17: 0 | E17: 3 | F17: green | G17: 1 | H17: 691 | I17: us | J17: 166 | K17: 4.719 | L17: 10 | M17: mww | N17: 595.854 | O17: -22.2844 | P17: 179.391 | Q17: the Fiji Islands | T17: =IF(C17="","",IF(ISNUMBER(C17),DATE(YEAR(C17),DAY(C17),MONTH(C17))+TIME(HOUR(C17),MINUTE(C17),SECOND(C17)),DATE(VALUE(MID(C17,7,4)),VALUE(MID(C17,4,2)),VALUE(MID(C17,1,2)))+TIME(VALUE(MID(C17,12,2)),VALUE(MID(C17,15,2)),0))) -> 45034.188 | U17: =ISNUMBER(T17) -> TRUE | V17: =ISNUMBER(C17) -> FALSE | W17: =IF(ISNUMBER(SEARCH(" km ",A17)),"Distance/Location","Named Region") -> Named Region | X17: =LOWER(M17) -> mww | Y17: =COUNTIFS($A$2:$A$1001,A17,$C$2:$C$1001,C17) -> 1 | Z17: =IF(Y17>1,"Duplicate","Unique") -> Unique | AA17: =IF(U17=TRUE,"Valid","Invalid") -> Valid
A18: M 7.0 - 96 km N of Tuban, Indonesia | B18: 7 | C18: 14/04/2023 09:55 | D18: 5 | E18: 3 | F18: green | G18: 0 | H18: 818 | I18: us | J18: 131 | K18: 1.881 | L18: 31 | M18: mww | N18: 594.028 | O18: -6.0255 | P18: 112.033 | Q18: Tuban, Indonesia | S18: Indonesia | T18: =IF(C18="","",IF(ISNUMBER(C18),DATE(YEAR(C18),DAY(C18),MONTH(C18))+TIME(HOUR(C18),MINUTE(C18),SECOND(C18)),DATE(VALUE(MID(C18,7,4)),VALUE(MID(C18,4,2)),VALUE(MID(C18,1,2)))+TIME(VALUE(MID(C18,12,2)),VALUE(MID(C18,15,2)),0))) -> 45030.413 | U18: =ISNUMBER(T18) -> TRUE | V18: =ISNUMBER(C18) -> FALSE | W18: =IF(ISNUMBER(SEARCH(" km ",A18)),"Distance/Location","Named Region") -> Distance/Location | X18: =LOWER(M18) -> mww | Y18: =COUNTIFS($A$2:$A$1001,A18,$C$2:$C$1001,C18) -> 1 | Z18: =IF(Y18>1,"Duplicate","Unique") -> Unique | AA18: =IF(U18=TRUE,"Valid","Invalid") -> Valid
A19: M 6.5 - near the east coast of the Kamchatka Peninsula, Russia | B19: 6.5 | C19: 44989.129 | D19: 7 | E19: 6 | F19: yellow | G19: 1 | H19: 655 | I19: us | J19: 104 | K19: 0.266 | L19: 30 | M19: mww | N19: 105.631 | O19: 52.7772 | P19: 158.484 | Q19: the Kamchatka Peninsula, Russia | R19: Asia | S19: Russian Federation (the) | T19: =IF(C19="","",IF(ISNUMBER(C19),DATE(YEAR(C19),DAY(C19),MONTH(C19))+TIME(HOUR(C19),MINUTE(C19),SECOND(C19)),DATE(VALUE(MID(C19,7,4)),VALUE(MID(C19,4,2)),VALUE(MID(C19,1,2)))+TIME(VALUE(MID(C19,12,2)),VALUE(MID(C19,15,2)),0))) -> 45019.129 | U19: =ISNUMBER(T19) -> TRUE | V19: =ISNUMBER(C19) -> TRUE | W19: =IF(ISNUMBER(SEARCH(" km ",A19)),"Distance/Location","Named Region") -> Named Region | X19: =LOWER(M19) -> mww | Y19: =COUNTIFS($A$2:$A$1001,A19,$C$2:$C$1001,C19) -> 1 | Z19: =IF(Y19>1,"Duplicate","Unique") -> Unique | AA19: =IF(U19=TRUE,"Valid","Invalid") -> Valid
A20: M 7.0 - New Guinea, Papua New Guinea | B20: 7 | C20: 44961.753 | D20: 7 | E20: 7 | F20: green | G20: 1 | H20: 781 | I20: us | J20: 105 | K20: 6.45 | L20: 31 | M20: mww | N20: 62.603 | O20: -4.2924 | P20: 143.155 | Q20: New Guinea, Papua New Guinea | R20: Asia | S20: Papua New Guinea | T20: =IF(C20="","",IF(ISNUMBER(C20),DATE(YEAR(C20),DAY(C20),MONTH(C20))+TIME(HOUR(C20),MINUTE(C20),SECOND(C20)),DATE(VALUE(MID(C20,7,4)),VALUE(MID(C20,4,2)),VALUE(MID(C20,1,2)))+TIME(VALUE(MID(C20,12,2)),VALUE(MID(C20,15,2)),0))) -> 45018.753 | U20: =ISNUMBER(T20) -> TRUE | V20: =ISNUMBER(C20) -> TRUE | W20: =IF(ISNUMBER(SEARCH(" km ",A20)),"Distance/Location","Named Region") -> Named Region | X20: =LOWER(M20) -> mww | Y20: =COUNTIFS($A$2:$A$1001,A20,$C$2:$C$1001,C20) -> 1 | Z20: =IF(Y20>1,"Duplicate","Unique") -> Unique | AA20: =IF(U20=TRUE,"Valid","Invalid") -> Valid
A21: M 6.5 - 84 km NNW of San Antonio de los Cobres, Argentina | B21: 6.5 | C21: 22/03/2023 16:00 | D21: 4 | E21: 4 | F21: green | G21: 0 | H21: 656 | I21: us | J21: 97 | K21: 1.622 | L21: 33 | M21: mww | N21: 209.976 | O21: -23.4797 | P21: -66.5108 | Q21: San Antonio de los Cobres, Argentina | R21: South America | S21: Argentina | T21: =IF(C21="","",IF(ISNUMBER(C21),DATE(YEAR(C21),DAY(C21),MONTH(C21))+TIME(HOUR(C21),MINUTE(C21),SECOND(C21)),DATE(VALUE(MID(C21,7,4)),VALUE(MID(C21,4,2)),VALUE(MID(C21,1,2)))+TIME(VALUE(MID(C21,12,2)),VALUE(MID(C21,15,2)),0))) -> 45007.667 | U21: =ISNUMBER(T21) -> TRUE | V21: =ISNUMBER(C21) -> FALSE | W21: =IF(ISNUMBER(SEARCH(" km ",A21)),"Distance/Location","Named Region") -> Distance/Location | X21: =LOWER(M21) -> mww | Y21: =COUNTIFS($A$2:$A$1001,A21,$C$2:$C$1001,C21) -> 1 | Z21: =IF(Y21>1,"Duplicate","Unique") -> Unique | AA21: =IF(U21=TRUE,"Valid","Invalid") -> Valid
A22: M 6.5 - 40 km SSE of Jurm, Afghanistan | B22: 6.5 | C22: 21/03/2023 16:47 | D22: 7 | E22: 5 | F22: green | G22: 0 | H22: 1350 | I22: us | J22: 134 | K22: 2.53 | L22: 13 | M22: mww | N22: 187.589 | O22: 36.5227 | P22: 70.9787 | Q22: Jurm, Afghanistan | R22: Asia | S22: Afghanistan | T22: =IF(C22="","",IF(ISNUMBER(C22),DATE(YEAR(C22),DAY(C22),MONTH(C22))+TIME(HOUR(C22),MINUTE(C22),SECOND(C22)),DATE(VALUE(MID(C22,7,4)),VALUE(MID(C22,4,2)),VALUE(MID(C22,1,2)))+TIME(VALUE(MID(C22,12,2)),VALUE(MID(C22,15,2)),0))) -> 45006.699 | U22: =ISNUMBER(T22) -> TRUE | V22: =ISNUMBER(C22) -> FALSE | W22: =IF(ISNUMBER(SEARCH(" km ",A22)),"Distance/Location","Named Region") -> Distance/Location | X22: =LOWER(M22) -> mww | Y22: =COUNTIFS($A$2:$A$1001,A22,$C$2:$C$1001,C22) -> 1 | Z22: =IF(Y22>1,"Duplicate","Unique") -> Unique | AA22: =IF(U22=TRUE,"Valid","Invalid") -> Valid
A23: M 6.8 - near the coast of Ecuador | B23: 6.8 | C23: 18/03/2023 17:12 | D23: 9 | E23: 7 | F23: orange | G23: 1 | H23: 1159 | I23: us | J23: 152 | K23: 0.709 | L23: 28 | M23: mww | N23: 65.842 | O23: -2.851 | P23: -79.8001 | Q23: Ecuador | R23: South America | S23: Ecuador | T23: =IF(C23="","",IF(ISNUMBER(C23),DATE(YEAR(C23),DAY(C23),MONTH(C23))+TIME(HOUR(C23),MINUTE(C23),SECOND(C23)),DATE(VALUE(MID(C23,7,4)),VALUE(MID(C23,4,2)),VALUE(MID(C23,1,2)))+TIME(VALUE(MID(C23,12,2)),VALUE(MID(C23,15,2)),0))) -> 45003.717 | U23: =ISNUMBER(T23) -> TRUE | V23: =ISNUMBER(C23) -> FALSE | W23: =IF(ISNUMBER(SEARCH(" km ",A23)),"Distance/Location","Named Region") -> Named Region | X23: =LOWER(M23) -> mww | Y23: =COUNTIFS($A$2:$A$1001,A23,$C$2:$C$1001,C23) -> 1 | Z23: =IF(Y23>1,"Duplicate","Unique") -> Unique | AA23: =IF(U23=TRUE,"Valid","Invalid") -> Valid
A24: M 7.0 - Kermadec Islands region | B24: 7 | C24: 16/03/2023 00:56 | D24: 8 | E24: 5 | F24: green | G24: 1 | H24: 756 | I24: us | J24: 116 | K24: 1.789 | L24: 22 | M24: mww | N24: 22.065 | O24: -30.1147 | P24: -176.112 | Q24: Kermadec Islands region | T24: =IF(C24="","",IF(ISNUMBER(C24),DATE(YEAR(C24),DAY(C24),MONTH(C24))+TIME(HOUR(C24),MINUTE(C24),SECOND(C24)),DATE(VALUE(MID(C24,7,4)),VALUE(MID(C24,4,2)),VALUE(MID(C24,1,2)))+TIME(VALUE(MID(C24,12,2)),VALUE(MID(C24,15,2)),0))) -> 45001.039 | U24: =ISNUMBER(T24) -> TRUE | V24: =ISNUMBER(C24) -> FALSE | W24: =IF(ISNUMBER(SEARCH(" km ",A24)),"Distance/Location","Named Region") -> Named Region | X24: =LOWER(M24) -> mww | Y24: =COUNTIFS($A$2:$A$1001,A24,$C$2:$C$1001,C24) -> 1 | Z24: =IF(Y24>1,"Duplicate","Unique") -> Unique | AA24: =IF(U24=TRUE,"Valid","Invalid") -> Valid
A25: M 6.9 - Kermadec Islands, New Zealand | B25: 6.9 | C25: 45019.278 | D25: 5 | E25: 5 | F25: green | G25: 1 | H25: 735 | I25: us | J25: 108 | K25: 0.784 | L25: 18 | M25: mww | N25: 205.681 | O25: -29.4748 | P25: -178.787 | Q25: Kermadec Islands, New Zealand | T25: =IF(C25="","",IF(ISNUMBER(C25),DATE(YEAR(C25),DAY(C25),MONTH(C25))+TIME(HOUR(C25),MINUTE(C25),SECOND(C25)),DATE(VALUE(MID(C25,7,4)),VALUE(MID(C25,4,2)),VALUE(MID(C25,1,2)))+TIME(VALUE(MID(C25,12,2)),VALUE(MID(C25,15,2)),0))) -> 44989.278 | U25: =ISNUMBER(T25) -> TRUE | V25: =ISNUMBER(C25) -> TRUE | W25: =IF(ISNUMBER(SEARCH(" km ",A25)),"Distance/Location","Named Region") -> Named Region | X25: =LOWER(M25) -> mww | Y25: =COUNTIFS($A$2:$A$1001,A25,$C$2:$C$1001,C25) -> 1 | Z25: =IF(Y25>1,"Duplicate","Unique") -> Unique | AA25: =IF(U25=TRUE,"Valid","Invalid") -> Valid
A26: M 6.5 - 86 km WSW of Port-Olry, Vanuatu | B26: 6.5 | C26: 44960.753 | D26: 7 | E26: 6 | F26: green | G26: 1 | H26: 653 | I26: us | J26: 66 | K26: 5.483 | L26: 45 | M26: mww | N26: 10 | O26: -15.3597 | P26: 166.385 | Q26: Port-Olry, Vanuatu | T26: =IF(C26="","",IF(ISNUMBER(C26),DATE(YEAR(C26),DAY(C26),MONTH(C26))+TIME(HOUR(C26),MINUTE(C26),SECOND(C26)),DATE(VALUE(MID(C26,7,4)),VALUE(MID(C26,4,2)),VALUE(MID(C26,1,2)))+TIME(VALUE(MID(C26,12,2)),VALUE(MID(C26,15,2)),0))) -> 44987.753 | U26: =ISNUMBER(T26) -> TRUE | V26: =ISNUMBER(C26) -> TRUE | W26: =IF(ISNUMBER(SEARCH(" km ",A26)),"Distance/Location","Named Region") -> Distance/Location | X26: =LOWER(M26) -> mww | Y26: =COUNTIFS($A$2:$A$1001,A26,$C$2:$C$1001,C26) -> 1 | Z26: =IF(Y26>1,"Duplicate","Unique") -> Unique | AA26: =IF(U26=TRUE,"Valid","Invalid") -> Valid
A27: M 6.5 - 108 km NW of Kimbe, Papua New Guinea | B27: 6.5 | C27: 44929.233 | D27: 4 | E27: 2 | F27: green | G27: 1 | H27: 652 | I27: us | J27: 115 | K27: 2.739 | L27: 20 | M27: mww | N27: 598.925 | O27: -4.8138 | P27: 149.487 | Q27: Kimbe, Papua New Guinea | S27: Papua New Guinea | T27: =IF(C27="","",IF(ISNUMBER(C27),DATE(YEAR(C27),DAY(C27),MONTH(C27))+TIME(HOUR(C27),MINUTE(C27),SECOND(C27)),DATE(VALUE(MID(C27,7,4)),VALUE(MID(C27,4,2)),VALUE(MID(C27,1,2)))+TIME(VALUE(MID(C27,12,2)),VALUE(MID(C27,15,2)),0))) -> 44986.233 | U27: =ISNUMBER(T27) -> TRUE | V27: =ISNUMBER(C27) -> TRUE | W27: =IF(ISNUMBER(SEARCH(" km ",A27)),"Distance/Location","Named Region") -> Distance/Location | X27: =LOWER(M27) -> mww | Y27: =COUNTIFS($A$2:$A$1001,A27,$C$2:$C$1001,C27) -> 1 | Z27: =IF(Y27>1,"Duplicate","Unique") -> Unique | AA27: =IF(U27=TRUE,"Valid","Invalid") -> Valid
A28: M 6.8 - 67 km W of Murghob, Tajikistan | B28: 6.8 | C28: 23/02/2023 00:37 | D28: 9 | E28: 7 | F28: green | G28: 0 | H28: 737 | I28: us | J28: 128 | K28: 1.783 | L28: 20 | M28: mww | N28: 20.522 | O28: 38.0726 | P28: 73.2077 | Q28: Murghob, Tajikistan | R28: Asia | S28: Tajikistan | T28: =IF(C28="","",IF(ISNUMBER(C28),DATE(YEAR(C28),DAY(C28),MONTH(C28))+TIME(HOUR(C28),MINUTE(C28),SECOND(C28)),DATE(VALUE(MID(C28,7,4)),VALUE(MID(C28,4,2)),VALUE(MID(C28,1,2)))+TIME(VALUE(MID(C28,12,2)),VALUE(MID(C28,15,2)),0))) -> 44980.026 | U28: =ISNUMBER(T28) -> TRUE | V28: =ISNUMBER(C28) -> FALSE | W28: =IF(ISNUMBER(SEARCH(" km ",A28)),"Distance/Location","Named Region") -> Distance/Location | X28: =LOWER(M28) -> mww | Y28: =COUNTIFS($A$2:$A$1001,A28,$C$2:$C$1001,C28) -> 1 | Z28: =IF(Y28>1,"Duplicate","Unique") -> Unique | AA28: =IF(U28=TRUE,"Valid","Invalid") -> Valid
A29: M 7.5 - 4 km SSE of Ekinözü, Turkey | B29: 7.5 | C29: 45079.433 | D29: 9 | E29: 9 | F29: orange | G29: 0 | H29: 1411 | I29: us | J29: 135 | K29: 0.85 | L29: 17 | M29: mww | N29: 10 | O29: 38.0235 | P29: 37.203 | Q29: Ekinözü, Turkey | R29: Asia | S29: Turkiye | T29: =IF(C29="","",IF(ISNUMBER(C29),DATE(YEAR(C29),DAY(C29),MONTH(C29))+TIME(HOUR(C29),MINUTE(C29),SECOND(C29)),DATE(VALUE(MID(C29,7,4)),VALUE(MID(C29,4,2)),VALUE(MID(C29,1,2)))+TIME(VALUE(MID(C29,12,2)),VALUE(MID(C29,15,2)),0))) -> 44963.433 | U29: =ISNUMBER(T29) -> TRUE | V29: =ISNUMBER(C29) -> TRUE | W29: =IF(ISNUMBER(SEARCH(" km ",A29)),"Distance/Location","Named Region") -> Distance/Location | X29: =LOWER(M29) -> mww | Y29: =COUNTIFS($A$2:$A$1001,A29,$C$2:$C$1001,C29) -> 1 | Z29: =IF(Y29>1,"Duplicate","Unique") -> Unique | AA29: =IF(U29=TRUE,"Valid","Invalid") -> Valid
A30: M 6.7 - 18 km ESE of Nurdağı, Turkey | B30: 6.7 | C30: 45079.061 | D30: 9 | E30: 8 | F30: yellow | G30: 0 | H30: 800 | I30: us | J30: 108 | K30: 0.218 | L30: 44 | M30: mww | N30: 14.497 | O30: 37.4135 | P30: 36.8306 | Q30: Nurdağı, Turkey | R30: Asia | S30: Turkiye | T30: =IF(C30="","",IF(ISNUMBER(C30),DATE(YEAR(C30),DAY(C30),MONTH(C30))+TIME(HOUR(C30),MINUTE(C30),SECOND(C30)),DATE(VALUE(MID(C30,7,4)),VALUE(MID(C30,4,2)),VALUE(MID(C30,1,2)))+TIME(VALUE(MID(C30,12,2)),VALUE(MID(C30,15,2)),0))) -> 44963.061 | U30: =ISNUMBER(T30) -> TRUE | V30: =ISNUMBER(C30) -> TRUE | W30: =IF(ISNUMBER(SEARCH(" km ",A30)),"Distance/Location","Named Region") -> Distance/Location | X30: =LOWER(M30) -> mww | Y30: =COUNTIFS($A$2:$A$1001,A30,$C$2:$C$1001,C30) -> 1 | Z30: =IF(Y30>1,"Duplicate","Unique") -> Unique | AA30: =IF(U30=TRUE,"Valid","Invalid") -> Valid
A31: M 7.8 - Central Turkey | B31: 7.8 | C31: 45079.053 | D31: 9 | E31: 9 | F31: red | G31: 0 | H31: 2910 | I31: us | J31: 118 | K31: 1.919 | L31: 32 | M31: mww | N31: 17.925 | O31: 37.2012 | P31: 36.9997 | Q31: Central Turkey | R31: Asia | S31: Turkiye | T31: =IF(C31="","",IF(ISNUMBER(C31),DATE(YEAR(C31),DAY(C31),MONTH(C31))+TIME(HOUR(C31),MINUTE(C31),SECOND(C31)),DATE(VALUE(MID(C31,7,4)),VALUE(MID(C31,4,2)),VALUE(MID(C31,1,2)))+TIME(VALUE(MID(C31,12,2)),VALUE(MID(C31,15,2)),0))) -> 44963.053 | U31: =ISNUMBER(T31) -> TRUE | V31: =ISNUMBER(C31) -> TRUE | W31: =IF(ISNUMBER(SEARCH(" km ",A31)),"Distance/Location","Named Region") -> Named Region | X31: =LOWER(M31) -> mww | Y31: =COUNTIFS($A$2:$A$1001,A31,$C$2:$C$1001,C31) -> 1 | Z31: =IF(Y31>1,"Duplicate","Unique") -> Unique | AA31: =IF(U31=TRUE,"Valid","Invalid") -> Valid
A32: M 6.8 - | B32: 6.8 | C32: 20/01/2023 22:09 | D32: 4 | E32: 3 | F32: green | G32: 0 | H32: 718 | I32: us | J32: 60 | K32: 5.129 | L32: 61 | M32: mww | N32: 610.671 | O32: -26.7209 | P32: -63.0394 | R32: South America | S32: Argentina | T32: =IF(C32="","",IF(ISNUMBER(C32),DATE(YEAR(C32),DAY(C32),MONTH(C32))+TIME(HOUR(C32),MINUTE(C32),SECOND(C32)),DATE(VALUE(MID(C32,7,4)),VALUE(MID(C32,4,2)),VALUE(MID(C32,1,2)))+TIME(VALUE(MID(C32,12,2)),VALUE(MID(C32,15,2)),0))) -> 44946.923 | U32: =ISNUMBER(T32) -> TRUE | V32: =ISNUMBER(C32) -> FALSE | W32: =IF(ISNUMBER(SEARCH(" km ",A32)),"Distance/Location","Named Region") -> Named Region | X32: =LOWER(M32) -> mww | Y32: =COUNTIFS($A$2:$A$1001,A32,$C$2:$C$1001,C32) -> 1 | Z32: =IF(Y32>1,"Duplicate","Unique") -> Unique | AA32: =IF(U32=TRUE,"Valid","Invalid") -> Valid
A33: M 7.0 - 153 km NW of Tobelo, Indonesia | B33: 7 | C33: 18/01/2023 06:06 | D33: 3 | E33: 5 | F33: green | G33: 1 | H33: 756 | I33: us | J33: 130 | K33: 1.974 | L33: 17 | M33: mwc | N33: 28.566 | O33: 2.7401 | P33: 127.051 | Q33: Tobelo, Indonesia | S33: Indonesia | T33: =IF(C33="","",IF(ISNUMBER(C33),DATE(YEAR(C33),DAY(C33),MONTH(C33))+TIME(HOUR(C33),MINUTE(C33),SECOND(C33)),DATE(VALUE(MID(C33,7,4)),VALUE(MID(C33,4,2)),VALUE(MID(C33,1,2)))+TIME(VALUE(MID(C33,12,2)),VALUE(MID(C33,15,2)),0))) -> 44944.254 | U33: =ISNUMBER(T33) -> TRUE | V33: =ISNUMBER(C33) -> FALSE | W33: =IF(ISNUMBER(SEARCH(" km ",A33)),"Distance/Location","Named Region") -> Distance/Location | X33: =LOWER(M33) -> mwc | Y33: =COUNTIFS($A$2:$A$1001,A33,$C$2:$C$1001,C33) -> 1 | Z33: =IF(Y33>1,"Duplicate","Unique") -> Unique | AA33: =IF(U33=TRUE,"Valid","Invalid") -> Valid
A34: M 7.6 - Pulau Pulau Tanimbar, Indonesia | B34: 7.6 | C34: 45170.741 | D34: 5 | E34: 7 | F34: green | G34: 0 | H34: 957 | I34: us | J34: 114 | K34: 1.575 | L34: 21 | M34: mww | N34: 105.249 | O34: -7.0852 | P34: 130.039 | Q34: Pulau Pulau Tanimbar, Indonesia | S34: Indonesia | T34: =IF(C34="","",IF(ISNUMBER(C34),DATE(YEAR(C34),DAY(C34),MONTH(C34))+TIME(HOUR(C34),MINUTE(C34),SECOND(C34)),DATE(VALUE(MID(C34,7,4)),VALUE(MID(C34,4,2)),VALUE(MID(C34,1,2)))+TIME(VALUE(MID(C34,12,2)),VALUE(MID(C34,15,2)),0))) -> 44935.741 | U34: =ISNUMBER(T34) -> TRUE | V34: =ISNUMBER(C34) -> TRUE | W34: =IF(ISNUMBER(SEARCH(" km ",A34)),"Distance/Location","Named Region") -> Named Region | X34: =LOWER(M34) -> mww | Y34: =COUNTIFS($A$2:$A$1001,A34,$C$2:$C$1001,C34) -> 1 | Z34: =IF(Y34>1,"Duplicate","Unique") -> Unique | AA34: =IF(U34=TRUE,"Valid","Invalid") -> Valid
A35: M 7.0 - Vanuatu | B35: 7 | C35: 45139.522 | D35: 8 | E35: 7 | F35: green | G35: 1 | H35: 768 | I35: us | J35: 116 | K35: 6.096 | L35: 36 | M35: mww | N35: 29 | O35: -14.9383 | P35: 166.878 | Q35: Vanuatu | S35: Vanuatu | T35: =IF(C35="","",IF(ISNUMBER(C35),DATE(YEAR(C35),DAY(C35),MONTH(C35))+TIME(HOUR(C35),MINUTE(C35),SECOND(C35)),DATE(VALUE(MID(C35,7,4)),VALUE(MID(C35,4,2)),VALUE(MID(C35,1,2)))+TIME(VALUE(MID(C35,12,2)),VALUE(MID(C35,15,2)),0))) -> 44934.522 | U35: =ISNUMBER(T35) -> TRUE | V35: =ISNUMBER(C35) -> TRUE | W35: =IF(ISNUMBER(SEARCH(" km ",A35)),"Distance/Location","Named Region") -> Named Region | X35: =LOWER(M35) -> mww | Y35: =COUNTIFS($A$2:$A$1001,A35,$C$2:$C$1001,C35) -> 1 | Z35: =IF(Y35>1,"Duplicate","Unique") -> Unique | AA35: =IF(U35=TRUE,"Valid","Invalid") -> Valid
A36: M 6.8 - 109 km NE of Hihifo, Tonga | B36: 6.8 | C36: 44663.808 | D36: 5 | E36: 5 | F36: green | G36: 1 | H36: 720 | I36: us | J36: 152 | K36: 2.587 | L36: 26 | M36: mww | N36: 38 | O36: -15.3983 | P36: -172.968 | Q36: Hihifo, Tonga | T36: =IF(C36="","",IF(ISNUMBER(C36),DATE(YEAR(C36),DAY(C36),MONTH(C36))+TIME(HOUR(C36),MINUTE(C36),SECOND(C36)),DATE(VALUE(MID(C36,7,4)),VALUE(MID(C36,4,2)),VALUE(MID(C36,1,2)))+TIME(VALUE(MID(C36,12,2)),VALUE(MID(C36,15,2)),0))) -> 44899.808 | U36: =ISNUMBER(T36) -> TRUE | V36: =ISNUMBER(C36) -> TRUE | W36: =IF(ISNUMBER(SEARCH(" km ",A36)),"Distance/Location","Named Region") -> Distance/Location | X36: =LOWER(M36) -> mww | Y36: =COUNTIFS($A$2:$A$1001,A36,$C$2:$C$1001,C36) -> 1 | Z36: =IF(Y36>1,"Duplicate","Unique") -> Unique | AA36: =IF(U36=TRUE,"Valid","Invalid") -> Valid
A37: M 7.0 - 18 km SW of Malango, Solomon Islands | B37: 7 | C37: 22/11/2022 02:03 | D37: 8 | E37: 7 | F37: green | G37: 1 | H37: 768 | I37: us | J37: 117 | K37: 0.509 | L37: 17 | M37: mww | N37: 14 | O37: -9.7963 | P37: 159.596 | Q37: Malango, Solomon Islands | R37: Oceania | S37: Solomon Islands | T37: =IF(C37="","",IF(ISNUMBER(C37),DATE(YEAR(C37),DAY(C37),MONTH(C37))+TIME(HOUR(C37),MINUTE(C37),SECOND(C37)),DATE(VALUE(MID(C37,7,4)),VALUE(MID(C37,4,2)),VALUE(MID(C37,1,2)))+TIME(VALUE(MID(C37,12,2)),VALUE(MID(C37,15,2)),0))) -> 44887.085 | U37: =ISNUMBER(T37) -> TRUE | V37: =ISNUMBER(C37) -> FALSE | W37: =IF(ISNUMBER(SEARCH(" km ",A37)),"Distance/Location","Named Region") -> Distance/Location | X37: =LOWER(M37) -> mww | Y37: =COUNTIFS($A$2:$A$1001,A37,$C$2:$C$1001,C37) -> 1 | Z37: =IF(Y37>1,"Duplicate","Unique") -> Unique | AA37: =IF(U37=TRUE,"Valid","Invalid") -> Valid
A38: M 6.9 - 204 km SW of Bengkulu, Indonesia | B38: 6.9 | C38: 18/11/2022 13:37 | D38: 4 | E38: 4 | F38: green | G38: 0 | H38: 735 | I38: us | J38: 99 | K38: 2.229 | L38: 34 | M38: mww | N38: 25 | O38: -4.9559 | P38: 100.738 | Q38: Bengkulu, Indonesia | T38: =IF(C38="","",IF(ISNUMBER(C38),DATE(YEAR(C38),DAY(C38),MONTH(C38))+TIME(HOUR(C38),MINUTE(C38),SECOND(C38)),DATE(VALUE(MID(C38,7,4)),VALUE(MID(C38,4,2)),VALUE(MID(C38,1,2)))+TIME(VALUE(MID(C38,12,2)),VALUE(MID(C38,15,2)),0))) -> 44883.567 | U38: =ISNUMBER(T38) -> TRUE | V38: =ISNUMBER(C38) -> FALSE | W38: =IF(ISNUMBER(SEARCH(" km ",A38)),"Distance/Location","Named Region") -> Distance/Location | X38: =LOWER(M38) -> mww | Y38: =COUNTIFS($A$2:$A$1001,A38,$C$2:$C$1001,C38) -> 1 | Z38: =IF(Y38>1,"Duplicate","Unique") -> Unique | AA38: =IF(U38=TRUE,"Valid","Invalid") -> Valid
A39: M 7.0 - | B39: 7 | C39: 44906.298 | D39: 3 | E39: 3 | F39: green | G39: 1 | H39: 755 | I39: us | J39: 147 | K39: 3.125 | L39: 18 | M39: mww | N39: 579 | O39: -20.0508 | P39: -178.346 | R39: Oceania | S39: Fiji | T39: =IF(C39="","",IF(ISNUMBER(C39),DATE(YEAR(C39),DAY(C39),MONTH(C39))+TIME(HOUR(C39),MINUTE(C39),SECOND(C39)),DATE(VALUE(MID(C39,7,4)),VALUE(MID(C39,4,2)),VALUE(MID(C39,1,2)))+TIME(VALUE(MID(C39,12,2)),VALUE(MID(C39,15,2)),0))) -> 44877.298 | U39: =ISNUMBER(T39) -> TRUE | V39: =ISNUMBER(C39) -> TRUE | W39: =IF(ISNUMBER(SEARCH(" km ",A39)),"Distance/Location","Named Region") -> Named Region | X39: =LOWER(M39) -> mww | Y39: =COUNTIFS($A$2:$A$1001,A39,$C$2:$C$1001,C39) -> 1 | Z39: =IF(Y39>1,"Duplicate","Unique") -> Unique | AA39: =IF(U39=TRUE,"Valid","Invalid") -> Valid
A40: M 7.3 - 205 km ESE of Neiafu, Tonga | B40: 7.3 | C40: 44876.45 | D40: 5 | E40: 5 | F40: green | G40: 1 | H40: 833 | I40: us | J40: 149 | K40: 1.865 | L40: 21 | M40: mww | N40: 37 | O40: -19.2918 | P40: -172.129 | Q40: Neiafu, Tonga | T40: =IF(C40="","",IF(ISNUMBER(C40),DATE(YEAR(C40),DAY(C40),MONTH(C40))+TIME(HOUR(C40),MINUTE(C40),SECOND(C40)),DATE(VALUE(MID(C40,7,4)),VALUE(MID(C40,4,2)),VALUE(MID(C40,1,2)))+TIME(VALUE(MID(C40,12,2)),VALUE(MID(C40,15,2)),0))) -> 44876.45 | U40: =ISNUMBER(T40) -> TRUE | V40: =ISNUMBER(C40) -> TRUE | W40: =IF(ISNUMBER(SEARCH(" km ",A40)),"Distance/Location","Named Region") -> Distance/Location | X40: =LOWER(M40) -> mww | Y40: =COUNTIFS($A$2:$A$1001,A40,$C$2:$C$1001,C40) -> 1 | Z40: =IF(Y40>1,"Duplicate","Unique") -> Unique | AA40: =IF(U40=TRUE,"Valid","Invalid") -> Valid
...

Sheet Cleaned_Data
A1: title | B1: magnitude | C1: date_time | D1: cdi | E1: mmi | F1: alert_cleaned | G1: tsunami | H1: sig | I1: net | J1: nst | K1: dmin | L1: gap | M1: magType | N1: depth | O1: latitude | P1: longitude | Q1: location_cleaned | R1: continent_cleaned | S1: country_cleaned | T1: date_status | U1: duplicate_count | V1: duplicate_flag | W1: alert_cleaned | X1: location_cleaned | Y1: continent_cleaned | Z1: country_cleaned | AA1: magType_normalized
A2: M 6.5 - 42 km W of Sola, Vanuatu | B2: 6.5 | C2: =Raw_Data!T2 -> 45154.533 | D2: 7 | E2: 4 | F2: green | G2: 0 | H2: 657 | I2: us | J2: 114 | K2: 7.177 | L2: 25 | M2: =Raw_Data!X2 -> mww | N2: 192.955 | O2: -13.8814 | P2: 167.158 | Q2: Sola, Vanuatu | S2: Vanuatu | T2: =IF(ISNUMBER(C2),"Valid","Invalid") -> Valid | U2: =COUNTIFS($A$2:$A$1001,A2,$B$2:$B$1001,B2,$C$2:$C$1001,C2) -> 1 | V2: =IF(U2>1,"Duplicate","Unique") -> Unique | W2: =IF(F2="","Unknown",F2) -> green | X2: =IF(Q2="","Unknown",Q2) -> Sola, Vanuatu | Y2: =IF(R2="","Unknown",R2) -> Unknown | Z2: =IF(S2="","Unknown",S2) -> Vanuatu | AA2: =LOWER(TRIM(M2)) -> mww
A3: M 6.5 - 43 km S of Intipucá, El Salvador | B3: 6.5 | C3: =Raw_Data!T3 -> 45126.015 | D3: 8 | E3: 6 | F3: yellow | G3: 0 | H3: 775 | I3: us | J3: 92 | K3: 0.679 | L3: 40 | M3: =Raw_Data!X3 -> mww | N3: 69.727 | O3: 12.814 | P3: -88.1265 | Q3: Intipucá, El Salvador | T3: =IF(ISNUMBER(C3),"Valid","Invalid") -> Valid | U3: =COUNTIFS($A$2:$A$1001,A3,$B$2:$B$1001,B3,$C$2:$C$1001,C3) -> 1 | V3: =IF(U3>1,"Duplicate","Unique") -> Unique | W3: =IF(F3="","Unknown",F3) -> yellow | X3: =IF(Q3="","Unknown",Q3) -> Intipucá, El Salvador | Y3: =IF(R3="","Unknown",R3) -> Unknown | Z3: =IF(S3="","Unknown",S3) -> Unknown | AA3: =LOWER(TRIM(M3)) -> mww
A4: M 6.6 - 25 km ESE of Loncopué, Argentina | B4: 6.6 | C4: =Raw_Data!T4 -> 45124.128 | D4: 7 | E4: 5 | F4: green | G4: 0 | H4: 899 | I4: us | J4: 70 | K4: 1.634 | L4: 28 | M4: =Raw_Data!X4 -> mww | N4: 171.371 | O4: -38.1911 | P4: -70.3731 | Q4: Loncopué, Argentina | R4: South America | S4: Argentina | T4: =IF(ISNUMBER(C4),"Valid","Invalid") -> Valid | U4: =COUNTIFS($A$2:$A$1001,A4,$B$2:$B$1001,B4,$C$2:$C$1001,C4) -> 1 | V4: =IF(U4>1,"Duplicate","Unique") -> Unique | W4: =IF(F4="","Unknown",F4) -> green | X4: =IF(Q4="","Unknown",Q4) -> Loncopué, Argentina | Y4: =IF(R4="","Unknown",R4) -> South America | Z4: =IF(S4="","Unknown",S4) -> Argentina | AA4: =LOWER(TRIM(M4)) -> mww
A5: M 7.2 - 98 km S of Sand Point, Alaska | B5: 7.2 | C5: =Raw_Data!T5 -> 45123.283 | D5: 6 | E5: 6 | F5: green | G5: 1 | H5: 860 | I5: us | J5: 173 | K5: 0.907 | L5: 36 | M5: =Raw_Data!X5 -> mww | N5: 32.571 | O5: 54.3844 | P5: -160.699 | Q5: Sand Point, Alaska | T5: =IF(ISNUMBER(C5),"Valid","Invalid") -> Valid | U5: =COUNTIFS($A$2:$A$1001,A5,$B$2:$B$1001,B5,$C$2:$C$1001,C5) -> 1 | V5: =IF(U5>1,"Duplicate","Unique") -> Unique | W5: =IF(F5="","Unknown",F5) -> green | X5: =IF(Q5="","Unknown",Q5) -> Sand Point, Alaska | Y5: =IF(R5="","Unknown",R5) -> Unknown | Z5: =IF(S5="","Unknown",S5) -> Unknown | AA5: =LOWER(TRIM(M5)) -> mww
A6: M 7.3 - Alaska Peninsula | B6: 7.3 | C6: =Raw_Data!T6 -> 45123.283 | D6: 0 | E6: 5 | G6: 1 | H6: 820 | I6: at | J6: 79 | K6: 0.879451 | L6: 172.8 | M6: =Raw_Data!X6 -> mi | N6: 21 | O6: 54.49 | P6: -160.796 | Q6: Alaska Peninsula | T6: =IF(ISNUMBER(C6),"Valid","Invalid") -> Valid | U6: =COUNTIFS($A$2:$A$1001,A6,$B$2:$B$1001,B6,$C$2:$C$1001,C6) -> 1 | V6: =IF(U6>1,"Duplicate","Unique") -> Unique | W6: =IF(F6="","Unknown",F6) -> Unknown | X6: =IF(Q6="","Unknown",Q6) -> Alaska Peninsula | Y6: =IF(R6="","Unknown",R6) -> Unknown | Z6: =IF(S6="","Unknown",S6) -> Unknown | AA6: =LOWER(TRIM(M6)) -> mi
A7: M 6.6 - 277 km NNE of Codrington, Antigua and Barbuda | B7: 6.6 | C7: =Raw_Data!T7 -> 45117.853 | D7: 5 | E7: 4 | F7: green | G7: 1 | H7: 802 | I7: us | J7: 95 | K7: 2.454 | L7: 37 | M7: =Raw_Data!X7 -> mww | N7: 10 | O7: 20.0196 | P7: -61.0955 | Q7: Codrington, Antigua and Barbuda | T7: =IF(ISNUMBER(C7),"Valid","Invalid") -> Valid | U7: =COUNTIFS($A$2:$A$1001,A7,$B$2:$B$1001,B7,$C$2:$C$1001,C7) -> 1 | V7: =IF(U7>1,"Duplicate","Unique") -> Unique | W7: =IF(F7="","Unknown",F7) -> green | X7: =IF(Q7="","Unknown",Q7) -> Codrington, Antigua and Barbuda | Y7: =IF(R7="","Unknown",R7) -> Unknown | Z7: =IF(S7="","Unknown",S7) -> Unknown | AA7: =LOWER(TRIM(M7)) -> mww
A8: M 6.9 - Tonga | B8: 6.9 | C8: =Raw_Data!T8 -> 45109.435 | D8: 4 | E8: 4 | F8: green | G8: 1 | H8: 741 | I8: us | J8: 136 | K8: 1.179 | L8: 23 | M8: =Raw_Data!X8 -> mww | N8: 229 | O8: -17.853 | P8: -174.937 | Q8: Tonga | T8: =IF(ISNUMBER(C8),"Valid","Invalid") -> Valid | U8: =COUNTIFS($A$2:$A$1001,A8,$B$2:$B$1001,B8,$C$2:$C$1001,C8) -> 1 | V8: =IF(U8>1,"Duplicate","Unique") -> Unique | W8: =IF(F8="","Unknown",F8) -> green | X8: =IF(Q8="","Unknown",Q8) -> Tonga | Y8: =IF(R8="","Unknown",R8) -> Unknown | Z8: =IF(S8="","Unknown",S8) -> Unknown | AA8: =LOWER(TRIM(M8)) -> mww
A9: M 7.2 - south of the Fiji Islands | B9: 7.2 | C9: =Raw_Data!T9 -> 45092.754 | D9: 8 | E9: 6 | F9: green | G9: 1 | H9: 804 | I9: us | J9: 85 | K9: 2.59 | L9: 24 | M9: =Raw_Data!X9 -> mww | N9: 167.404 | O9: -22.9824 | P9: -177.208 | Q9: the Fiji Islands | T9: =IF(ISNUMBER(C9),"Valid","Invalid") -> Valid | U9: =COUNTIFS($A$2:$A$1001,A9,$B$2:$B$1001,B9,$C$2:$C$1001,C9) -> 1 | V9: =IF(U9>1,"Duplicate","Unique") -> Unique | W9: =IF(F9="","Unknown",F9) -> green | X9: =IF(Q9="","Unknown",Q9) -> the Fiji Islands | Y9: =IF(R9="","Unknown",R9) -> Unknown | Z9: =IF(S9="","Unknown",S9) -> Unknown | AA9: =LOWER(TRIM(M9)) -> mww
A10: M 6.6 - Panama-Colombia border region | B10: 6.6 | C10: =Raw_Data!T10 -> 45071.128 | D10: 6 | E10: 6 | F10: green | G10: 1 | H10: 733 | I10: us | J10: 50 | K10: 2.163 | L10: 129 | M10: =Raw_Data!X10 -> mww | N10: 10 | O10: 8.8894 | P10: -77.1231 | Q10: Panama-Colombia border region | S10: Colombia | T10: =IF(ISNUMBER(C10),"Valid","Invalid") -> Valid | U10: =COUNTIFS($A$2:$A$1001,A10,$B$2:$B$1001,B10,$C$2:$C$1001,C10) -> 1 | V10: =IF(U10>1,"Duplicate","Unique") -> Unique | W10: =IF(F10="","Unknown",F10) -> green | X10: =IF(Q10="","Unknown",Q10) -> Panama-Colombia border region | Y10: =IF(R10="","Unknown",R10) -> Unknown | Z10: =IF(S10="","Unknown",S10) -> Colombia | AA10: =LOWER(TRIM(M10)) -> mww
A11: M 7.1 - southeast of the Loyalty Islands | B11: 7.1 | C11: =Raw_Data!T11 -> 45066.077 | D11: 3 | E11: 4 | F11: green | G11: 1 | H11: 777 | I11: us | J11: 98 | K11: 2.812 | L11: 56 | M11: =Raw_Data!X11 -> mww | N11: 35.981 | O11: -23.0622 | P11: 170.456 | Q11: the Loyalty Islands | T11: =IF(ISNUMBER(C11),"Valid","Invalid") -> Valid | U11: =COUNTIFS($A$2:$A$1001,A11,$B$2:$B$1001,B11,$C$2:$C$1001,C11) -> 1 | V11: =IF(U11>1,"Duplicate","Unique") -> Unique | W11: =IF(F11="","Unknown",F11) -> green | X11: =IF(Q11="","Unknown",Q11) -> the Loyalty Islands | Y11: =IF(R11="","Unknown",R11) -> Unknown | Z11: =IF(S11="","Unknown",S11) -> Unknown | AA11: =LOWER(TRIM(M11)) -> mww
A12: M 7.7 - southeast of the Loyalty Islands | B12: 7.7 | C12: =Raw_Data!T12 -> 45065.123 | D12: 5 | E12: 4 | F12: green | G12: 1 | H12: 927 | I12: us | J12: 277 | K12: 3.111 | L12: 15 | M12: =Raw_Data!X12 -> mww | N12: 18.027 | O12: -23.2286 | P12: 170.694 | Q12: the Loyalty Islands | T12: =IF(ISNUMBER(C12),"Valid","Invalid") -> Valid | U12: =COUNTIFS($A$2:$A$1001,A12,$B$2:$B$1001,B12,$C$2:$C$1001,C12) -> 1 | V12: =IF(U12>1,"Duplicate","Unique") -> Unique | W12: =IF(F12="","Unknown",F12) -> green | X12: =IF(Q12="","Unknown",Q12) -> the Loyalty Islands | Y12: =IF(R12="","Unknown",R12) -> Unknown | Z12: =IF(S12="","Unknown",S12) -> Unknown | AA12: =LOWER(TRIM(M12)) -> mww
A13: M 7.6 - 95 km WNW of Hihifo, Tonga | B13: 7.6 | C13: =Raw_Data!T13 -> 45056.668 | D13: 8 | E13: 6 | F13: green | G13: 1 | H13: 907 | I13: us | J13: 111 | K13: 3.631 | L13: 17 | M13: =Raw_Data!X13 -> mww | N13: 210.097 | O13: -15.6002 | P13: -174.608 | Q13: Hihifo, Tonga | T13: =IF(ISNUMBER(C13),"Valid","Invalid") -> Valid | U13: =COUNTIFS($A$2:$A$1001,A13,$B$2:$B$1001,B13,$C$2:$C$1001,C13) -> 1 | V13: =IF(U13>1,"Duplicate","Unique") -> Unique | W13: =IF(F13="","Unknown",F13) -> green | X13: =IF(Q13="","Unknown",Q13) -> Hihifo, Tonga | Y13: =IF(R13="","Unknown",R13) -> Unknown | Z13: =IF(S13="","Unknown",S13) -> Unknown | AA13: =LOWER(TRIM(M13)) -> mww
A14: M 6.6 - south of the Fiji Islands | B14: 6.6 | C14: =Raw_Data!T14 -> 45044.134 | D14: 0 | E14: 2 | F14: green | G14: 0 | H14: 670 | I14: us | J14: 52 | K14: 5.123 | L14: 50 | M14: =Raw_Data!X14 -> mww | N14: 598.467 | O14: -25.2657 | P14: 178.424 | Q14: the Fiji Islands | T14: =IF(ISNUMBER(C14),"Valid","Invalid") -> Valid | U14: =COUNTIFS($A$2:$A$1001,A14,$B$2:$B$1001,B14,$C$2:$C$1001,C14) -> 1 | V14: =IF(U14>1,"Duplicate","Unique") -> Unique | W14: =IF(F14="","Unknown",F14) -> green | X14: =IF(Q14="","Unknown",Q14) -> the Fiji Islands | Y14: =IF(R14="","Unknown",R14) -> Unknown | Z14: =IF(S14="","Unknown",S14) -> Unknown | AA14: =LOWER(TRIM(M14)) -> mww
A15: M 7.1 - 170 km SSE of Teluk Dalam, Indonesia | B15: 7.1 | C15: =Raw_Data!T15 -> 45040.833 | D15: 9 | E15: 7 | F15: green | G15: 0 | H15: 838 | I15: us | J15: 70 | K15: 2.282 | L15: 58 | M15: =Raw_Data!X15 -> mww | N15: 15.462 | O15: -0.781 | P15: 98.5339 | Q15: Teluk Dalam, Indonesia | S15: Indonesia | T15: =IF(ISNUMBER(C15),"Valid","Invalid") -> Valid | U15: =COUNTIFS($A$2:$A$1001,A15,$B$2:$B$1001,B15,$C$2:$C$1001,C15) -> 1 | V15: =IF(U15>1,"Duplicate","Unique") -> Unique | W15: =IF(F15="","Unknown",F15) -> green | X15: =IF(Q15="","Unknown",Q15) -> Teluk Dalam, Indonesia | Y15: =IF(R15="","Unknown",R15) -> Unknown | Z15: =IF(S15="","Unknown",S15) -> Indonesia | AA15: =LOWER(TRIM(M15)) -> mww
A16: M 7.1 - Kermadec Islands, New Zealand | B16: 7.1 | C16: =Raw_Data!T16 -> 45040.028 | D16: 8 | E16: 7 | F16: green | G16: 1 | H16: 777 | I16: us | J16: 126 | K16: 0.708 | L16: 23 | M16: =Raw_Data!X16 -> mww | N16: 43.063 | O16: -30.0249 | P16: -177.897 | Q16: Kermadec Islands, New Zealand | T16: =IF(ISNUMBER(C16),"Valid","Invalid") -> Valid | U16: =COUNTIFS($A$2:$A$1001,A16,$B$2:$B$1001,B16,$C$2:$C$1001,C16) -> 1 | V16: =IF(U16>1,"Duplicate","Unique") -> Unique | W16: =IF(F16="","Unknown",F16) -> green | X16: =IF(Q16="","Unknown",Q16) -> Kermadec Islands, New Zealand | Y16: =IF(R16="","Unknown",R16) -> Unknown | Z16: =IF(S16="","Unknown",S16) -> Unknown | AA16: =LOWER(TRIM(M16)) -> mww
A17: M 6.7 - south of the Fiji Islands | B17: 6.7 | C17: =Raw_Data!T17 -> 45034.188 | D17: 0 | E17: 3 | F17: green | G17: 1 | H17: 691 | I17: us | J17: 166 | K17: 4.719 | L17: 10 | M17: =Raw_Data!X17 -> mww | N17: 595.854 | O17: -22.2844 | P17: 179.391 | Q17: the Fiji Islands | T17: =IF(ISNUMBER(C17),"Valid","Invalid") -> Valid | U17: =COUNTIFS($A$2:$A$1001,A17,$B$2:$B$1001,B17,$C$2:$C$1001,C17) -> 1 | V17: =IF(U17>1,"Duplicate","Unique") -> Unique | W17: =IF(F17="","Unknown",F17) -> green | X17: =IF(Q17="","Unknown",Q17) -> the Fiji Islands | Y17: =IF(R17="","Unknown",R17) -> Unknown | Z17: =IF(S17="","Unknown",S17) -> Unknown | AA17: =LOWER(TRIM(M17)) -> mww
A18: M 7.0 - 96 km N of Tuban, Indonesia | B18: 7 | C18: =Raw_Data!T18 -> 45030.413 | D18: 5 | E18: 3 | F18: green | G18: 0 | H18: 818 | I18: us | J18: 131 | K18: 1.881 | L18: 31 | M18: =Raw_Data!X18 -> mww | N18: 594.028 | O18: -6.0255 | P18: 112.033 | Q18: Tuban, Indonesia | S18: Indonesia | T18: =IF(ISNUMBER(C18),"Valid","Invalid") -> Valid | U18: =COUNTIFS($A$2:$A$1001,A18,$B$2:$B$1001,B18,$C$2:$C$1001,C18) -> 1 | V18: =IF(U18>1,"Duplicate","Unique") -> Unique | W18: =IF(F18="","Unknown",F18) -> green | X18: =IF(Q18="","Unknown",Q18) -> Tuban, Indonesia | Y18: =IF(R18="","Unknown",R18) -> Unknown | Z18: =IF(S18="","Unknown",S18) -> Indonesia | AA18: =LOWER(TRIM(M18)) -> mww
A19: M 6.5 - near the east coast of the Kamchatka Peninsula, Russia | B19: 6.5 | C19: =Raw_Data!T19 -> 45019.129 | D19: 7 | E19: 6 | F19: yellow | G19: 1 | H19: 655 | I19: us | J19: 104 | K19: 0.266 | L19: 30 | M19: =Raw_Data!X19 -> mww | N19: 105.631 | O19: 52.7772 | P19: 158.484 | Q19: the Kamchatka Peninsula, Russia | R19: Asia | S19: Russian Federation (the) | T19: =IF(ISNUMBER(C19),"Valid","Invalid") -> Valid | U19: =COUNTIFS($A$2:$A$1001,A19,$B$2:$B$1001,B19,$C$2:$C$1001,C19) -> 1 | V19: =IF(U19>1,"Duplicate","Unique") -> Unique | W19: =IF(F19="","Unknown",F19) -> yellow | X19: =IF(Q19="","Unknown",Q19) -> the Kamchatka Peninsula, Russia | Y19: =IF(R19="","Unknown",R19) -> Asia | Z19: =IF(S19="","Unknown",S19) -> Russian Federation (the) | AA19: =LOWER(TRIM(M19)) -> mww
A20: M 7.0 - New Guinea, Papua New Guinea | B20: 7 | C20: =Raw_Data!T20 -> 45018.753 | D20: 7 | E20: 7 | F20: green | G20: 1 | H20: 781 | I20: us | J20: 105 | K20: 6.45 | L20: 31 | M20: =Raw_Data!X20 -> mww | N20: 62.603 | O20: -4.2924 | P20: 143.155 | Q20: New Guinea, Papua New Guinea | R20: Asia | S20: Papua New Guinea | T20: =IF(ISNUMBER(C20),"Valid","Invalid") -> Valid | U20: =COUNTIFS($A$2:$A$1001,A20,$B$2:$B$1001,B20,$C$2:$C$1001,C20) -> 1 | V20: =IF(U20>1,"Duplicate","Unique") -> Unique | W20: =IF(F20="","Unknown",F20) -> green | X20: =IF(Q20="","Unknown",Q20) -> New Guinea, Papua New Guinea | Y20: =IF(R20="","Unknown",R20) -> Asia | Z20: =IF(S20="","Unknown",S20) -> Papua New Guinea | AA20: =LOWER(TRIM(M20)) -> mww
A21: M 6.5 - 84 km NNW of San Antonio de los Cobres, Argentina | B21: 6.5 | C21: =Raw_Data!T21 -> 45007.667 | D21: 4 | E21: 4 | F21: green | G21: 0 | H21: 656 | I21: us | J21: 97 | K21: 1.622 | L21: 33 | M21: =Raw_Data!X21 -> mww | N21: 209.976 | O21: -23.4797 | P21: -66.5108 | Q21: San Antonio de los Cobres, Argentina | R21: South America | S21: Argentina | T21: =IF(ISNUMBER(C21),"Valid","Invalid") -> Valid | U21: =COUNTIFS($A$2:$A$1001,A21,$B$2:$B$1001,B21,$C$2:$C$1001,C21) -> 1 | V21: =IF(U21>1,"Duplicate","Unique") -> Unique | W21: =IF(F21="","Unknown",F21) -> green | X21: =IF(Q21="","Unknown",Q21) -> San Antonio de los Cobres, Argentina | Y21: =IF(R21="","Unknown",R21) -> South America | Z21: =IF(S21="","Unknown",S21) -> Argentina | AA21: =LOWER(TRIM(M21)) -> mww
A22: M 6.5 - 40 km SSE of Jurm, Afghanistan | B22: 6.5 | C22: =Raw_Data!T22 -> 45006.699 | D22: 7 | E22: 5 | F22: green | G22: 0 | H22: 1350 | I22: us | J22: 134 | K22: 2.53 | L22: 13 | M22: =Raw_Data!X22 -> mww | N22: 187.589 | O22: 36.5227 | P22: 70.9787 | Q22: Jurm, Afghanistan | R22: Asia | S22: Afghanistan | T22: =IF(ISNUMBER(C22),"Valid","Invalid") -> Valid | U22: =COUNTIFS($A$2:$A$1001,A22,$B$2:$B$1001,B22,$C$2:$C$1001,C22) -> 1 | V22: =IF(U22>1,"Duplicate","Unique") -> Unique | W22: =IF(F22="","Unknown",F22) -> green | X22: =IF(Q22="","Unknown",Q22) -> Jurm, Afghanistan | Y22: =IF(R22="","Unknown",R22) -> Asia | Z22: =IF(S22="","Unknown",S22) -> Afghanistan | AA22: =LOWER(TRIM(M22)) -> mww
A23: M 6.8 - near the coast of Ecuador | B23: 6.8 | C23: =Raw_Data!T23 -> 45003.717 | D23: 9 | E23: 7 | F23: orange | G23: 1 | H23: 1159 | I23: us | J23: 152 | K23: 0.709 | L23: 28 | M23: =Raw_Data!X23 -> mww | N23: 65.842 | O23: -2.851 | P23: -79.8001 | Q23: Ecuador | R23: South America | S23: Ecuador | T23: =IF(ISNUMBER(C23),"Valid","Invalid") -> Valid | U23: =COUNTIFS($A$2:$A$1001,A23,$B$2:$B$1001,B23,$C$2:$C$1001,C23) -> 1 | V23: =IF(U23>1,"Duplicate","Unique") -> Unique | W23: =IF(F23="","Unknown",F23) -> orange | X23: =IF(Q23="","Unknown",Q23) -> Ecuador | Y23: =IF(R23="","Unknown",R23) -> South America | Z23: =IF(S23="","Unknown",S23) -> Ecuador | AA23: =LOWER(TRIM(M23)) -> mww
A24: M 7.0 - Kermadec Islands region | B24: 7 | C24: =Raw_Data!T24 -> 45001.039 | D24: 8 | E24: 5 | F24: green | G24: 1 | H24: 756 | I24: us | J24: 116 | K24: 1.789 | L24: 22 | M24: =Raw_Data!X24 -> mww | N24: 22.065 | O24: -30.1147 | P24: -176.112 | Q24: Kermadec Islands region | T24: =IF(ISNUMBER(C24),"Valid","Invalid") -> Valid | U24: =COUNTIFS($A$2:$A$1001,A24,$B$2:$B$1001,B24,$C$2:$C$1001,C24) -> 1 | V24: =IF(U24>1,"Duplicate","Unique") -> Unique | W24: =IF(F24="","Unknown",F24) -> green | X24: =IF(Q24="","Unknown",Q24) -> Kermadec Islands region | Y24: =IF(R24="","Unknown",R24) -> Unknown | Z24: =IF(S24="","Unknown",S24) -> Unknown | AA24: =LOWER(TRIM(M24)) -> mww
A25: M 6.9 - Kermadec Islands, New Zealand | B25: 6.9 | C25: =Raw_Data!T25 -> 44989.278 | D25: 5 | E25: 5 | F25: green | G25: 1 | H25: 735 | I25: us | J25: 108 | K25: 0.784 | L25: 18 | M25: =Raw_Data!X25 -> mww | N25: 205.681 | O25: -29.4748 | P25: -178.787 | Q25: Kermadec Islands, New Zealand | T25: =IF(ISNUMBER(C25),"Valid","Invalid") -> Valid | U25: =COUNTIFS($A$2:$A$1001,A25,$B$2:$B$1001,B25,$C$2:$C$1001,C25) -> 1 | V25: =IF(U25>1,"Duplicate","Unique") -> Unique | W25: =IF(F25="","Unknown",F25) -> green | X25: =IF(Q25="","Unknown",Q25) -> Kermadec Islands, New Zealand | Y25: =IF(R25="","Unknown",R25) -> Unknown | Z25: =IF(S25="","Unknown",S25) -> Unknown | AA25: =LOWER(TRIM(M25)) -> mww
A26: M 6.5 - 86 km WSW of Port-Olry, Vanuatu | B26: 6.5 | C26: =Raw_Data!T26 -> 44987.753 | D26: 7 | E26: 6 | F26: green | G26: 1 | H26: 653 | I26: us | J26: 66 | K26: 5.483 | L26: 45 | M26: =Raw_Data!X26 -> mww | N26: 10 | O26: -15.3597 | P26: 166.385 | Q26: Port-Olry, Vanuatu | T26: =IF(ISNUMBER(C26),"Valid","Invalid") -> Valid | U26: =COUNTIFS($A$2:$A$1001,A26,$B$2:$B$1001,B26,$C$2:$C$1001,C26) -> 1 | V26: =IF(U26>1,"Duplicate","Unique") -> Unique | W26: =IF(F26="","Unknown",F26) -> green | X26: =IF(Q26="","Unknown",Q26) -> Port-Olry, Vanuatu | Y26: =IF(R26="","Unknown",R26) -> Unknown | Z26: =IF(S26="","Unknown",S26) -> Unknown | AA26: =LOWER(TRIM(M26)) -> mww
A27: M 6.5 - 108 km NW of Kimbe, Papua New Guinea | B27: 6.5 | C27: =Raw_Data!T27 -> 44986.233 | D27: 4 | E27: 2 | F27: green | G27: 1 | H27: 652 | I27: us | J27: 115 | K27: 2.739 | L27: 20 | M27: =Raw_Data!X27 -> mww | N27: 598.925 | O27: -4.8138 | P27: 149.487 | Q27: Kimbe, Papua New Guinea | S27: Papua New Guinea | T27: =IF(ISNUMBER(C27),"Valid","Invalid") -> Valid | U27: =COUNTIFS($A$2:$A$1001,A27,$B$2:$B$1001,B27,$C$2:$C$1001,C27) -> 1 | V27: =IF(U27>1,"Duplicate","Unique") -> Unique | W27: =IF(F27="","Unknown",F27) -> green | X27: =IF(Q27="","Unknown",Q27) -> Kimbe, Papua New Guinea | Y27: =IF(R27="","Unknown",R27) -> Unknown | Z27: =IF(S27="","Unknown",S27) -> Papua New Guinea | AA27: =LOWER(TRIM(M27)) -> mww
A28: M 6.8 - 67 km W of Murghob, Tajikistan | B28: 6.8 | C28: =Raw_Data!T28 -> 44980.026 | D28: 9 | E28: 7 | F28: green | G28: 0 | H28: 737 | I28: us | J28: 128 | K28: 1.783 | L28: 20 | M28: =Raw_Data!X28 -> mww | N28: 20.522 | O28: 38.0726 | P28: 73.2077 | Q28: Murghob, Tajikistan | R28: Asia | S28: Tajikistan | T28: =IF(ISNUMBER(C28),"Valid","Invalid") -> Valid | U28: =COUNTIFS($A$2:$A$1001,A28,$B$2:$B$1001,B28,$C$2:$C$1001,C28) -> 1 | V28: =IF(U28>1,"Duplicate","Unique") -> Unique | W28: =IF(F28="","Unknown",F28) -> green | X28: =IF(Q28="","Unknown",Q28) -> Murghob, Tajikistan | Y28: =IF(R28="","Unknown",R28) -> Asia | Z28: =IF(S28="","Unknown",S28) -> Tajikistan | AA28: =LOWER(TRIM(M28)) -> mww
A29: M 7.5 - 4 km SSE of Ekinözü, Turkey | B29: 7.5 | C29: =Raw_Data!T29 -> 44963.433 | D29: 9 | E29: 9 | F29: orange | G29: 0 | H29: 1411 | I29: us | J29: 135 | K29: 0.85 | L29: 17 | M29: =Raw_Data!X29 -> mww | N29: 10 | O29: 38.0235 | P29: 37.203 | Q29: Ekinözü, Turkey | R29: Asia | S29: Turkiye | T29: =IF(ISNUMBER(C29),"Valid","Invalid") -> Valid | U29: =COUNTIFS($A$2:$A$1001,A29,$B$2:$B$1001,B29,$C$2:$C$1001,C29) -> 1 | V29: =IF(U29>1,"Duplicate","Unique") -> Unique | W29: =IF(F29="","Unknown",F29) -> orange | X29: =IF(Q29="","Unknown",Q29) -> Ekinözü, Turkey | Y29: =IF(R29="","Unknown",R29) -> Asia | Z29: =IF(S29="","Unknown",S29) -> Turkiye | AA29: =LOWER(TRIM(M29)) -> mww
A30: M 6.7 - 18 km ESE of Nurdağı, Turkey | B30: 6.7 | C30: =Raw_Data!T30 -> 44963.061 | D30: 9 | E30: 8 | F30: yellow | G30: 0 | H30: 800 | I30: us | J30: 108 | K30: 0.218 | L30: 44 | M30: =Raw_Data!X30 -> mww | N30: 14.497 | O30: 37.4135 | P30: 36.8306 | Q30: Nurdağı, Turkey | R30: Asia | S30: Turkiye | T30: =IF(ISNUMBER(C30),"Valid","Invalid") -> Valid | U30: =COUNTIFS($A$2:$A$1001,A30,$B$2:$B$1001,B30,$C$2:$C$1001,C30) -> 1 | V30: =IF(U30>1,"Duplicate","Unique") -> Unique | W30: =IF(F30="","Unknown",F30) -> yellow | X30: =IF(Q30="","Unknown",Q30) -> Nurdağı, Turkey | Y30: =IF(R30="","Unknown",R30) -> Asia | Z30: =IF(S30="","Unknown",S30) -> Turkiye | AA30: =LOWER(TRIM(M30)) -> mww
A31: M 7.8 - Central Turkey | B31: 7.8 | C31: =Raw_Data!T31 -> 44963.053 | D31: 9 | E31: 9 | F31: red | G31: 0 | H31: 2910 | I31: us | J31: 118 | K31: 1.919 | L31: 32 | M31: =Raw_Data!X31 -> mww | N31: 17.925 | O31: 37.2012 | P31: 36.9997 | Q31: Central Turkey | R31: Asia | S31: Turkiye | T31: =IF(ISNUMBER(C31),"Valid","Invalid") -> Valid | U31: =COUNTIFS($A$2:$A$1001,A31,$B$2:$B$1001,B31,$C$2:$C$1001,C31) -> 1 | V31: =IF(U31>1,"Duplicate","Unique") -> Unique | W31: =IF(F31="","Unknown",F31) -> red | X31: =IF(Q31="","Unknown",Q31) -> Central Turkey | Y31: =IF(R31="","Unknown",R31) -> Asia | Z31: =IF(S31="","Unknown",S31) -> Turkiye | AA31: =LOWER(TRIM(M31)) -> mww
A32: M 6.8 - | B32: 6.8 | C32: =Raw_Data!T32 -> 44946.923 | D32: 4 | E32: 3 | F32: green | G32: 0 | H32: 718 | I32: us | J32: 60 | K32: 5.129 | L32: 61 | M32: =Raw_Data!X32 -> mww | N32: 610.671 | O32: -26.7209 | P32: -63.0394 | R32: South America | S32: Argentina | T32: =IF(ISNUMBER(C32),"Valid","Invalid") -> Valid | U32: =COUNTIFS($A$2:$A$1001,A32,$B$2:$B$1001,B32,$C$2:$C$1001,C32) -> 1 | V32: =IF(U32>1,"Duplicate","Unique") -> Unique | W32: =IF(F32="","Unknown",F32) -> green | X32: =IF(Q32="","Unknown",Q32) -> Unknown | Y32: =IF(R32="","Unknown",R32) -> South America | Z32: =IF(S32="","Unknown",S32) -> Argentina | AA32: =LOWER(TRIM(M32)) -> mww
A33: M 7.0 - 153 km NW of Tobelo, Indonesia | B33: 7 | C33: =Raw_Data!T33 -> 44944.254 | D33: 3 | E33: 5 | F33: green | G33: 1 | H33: 756 | I33: us | J33: 130 | K33: 1.974 | L33: 17 | M33: =Raw_Data!X33 -> mwc | N33: 28.566 | O33: 2.7401 | P33: 127.051 | Q33: Tobelo, Indonesia | S33: Indonesia | T33: =IF(ISNUMBER(C33),"Valid","Invalid") -> Valid | U33: =COUNTIFS($A$2:$A$1001,A33,$B$2:$B$1001,B33,$C$2:$C$1001,C33) -> 1 | V33: =IF(U33>1,"Duplicate","Unique") -> Unique | W33: =IF(F33="","Unknown",F33) -> green | X33: =IF(Q33="","Unknown",Q33) -> Tobelo, Indonesia | Y33: =IF(R33="","Unknown",R33) -> Unknown | Z33: =IF(S33="","Unknown",S33) -> Indonesia | AA33: =LOWER(TRIM(M33)) -> mwc
A34: M 7.6 - Pulau Pulau Tanimbar, Indonesia | B34: 7.6 | C34: =Raw_Data!T34 -> 44935.741 | D34: 5 | E34: 7 | F34: green | G34: 0 | H34: 957 | I34: us | J34: 114 | K34: 1.575 | L34: 21 | M34: =Raw_Data!X34 -> mww | N34: 105.249 | O34: -7.0852 | P34: 130.039 | Q34: Pulau Pulau Tanimbar, Indonesia | S34: Indonesia | T34: =IF(ISNUMBER(C34),"Valid","Invalid") -> Valid | U34: =COUNTIFS($A$2:$A$1001,A34,$B$2:$B$1001,B34,$C$2:$C$1001,C34) -> 1 | V34: =IF(U34>1,"Duplicate","Unique") -> Unique | W34: =IF(F34="","Unknown",F34) -> green | X34: =IF(Q34="","Unknown",Q34) -> Pulau Pulau Tanimbar, Indonesia | Y34: =IF(R34="","Unknown",R34) -> Unknown | Z34: =IF(S34="","Unknown",S34) -> Indonesia | AA34: =LOWER(TRIM(M34)) -> mww
A35: M 7.0 - Vanuatu | B35: 7 | C35: =Raw_Data!T35 -> 44934.522 | D35: 8 | E35: 7 | F35: green | G35: 1 | H35: 768 | I35: us | J35: 116 | K35: 6.096 | L35: 36 | M35: =Raw_Data!X35 -> mww | N35: 29 | O35: -14.9383 | P35: 166.878 | Q35: Vanuatu | S35: Vanuatu | T35: =IF(ISNUMBER(C35),"Valid","Invalid") -> Valid | U35: =COUNTIFS($A$2:$A$1001,A35,$B$2:$B$1001,B35,$C$2:$C$1001,C35) -> 1 | V35: =IF(U35>1,"Duplicate","Unique") -> Unique | W35: =IF(F35="","Unknown",F35) -> green | X35: =IF(Q35="","Unknown",Q35) -> Vanuatu | Y35: =IF(R35="","Unknown",R35) -> Unknown | Z35: =IF(S35="","Unknown",S35) -> Vanuatu | AA35: =LOWER(TRIM(M35)) -> mww
